[2025-04-22T10:24:26.738-0300] {local_task_job_runner.py:123} INFO - ::group::Pre task execution logs
[2025-04-22T10:24:26.754-0300] {taskinstance.py:2614} INFO - Dependencies all met for dep_context=non-requeueable deps ti=<TaskInstance: integracao_api.integracao_api manual__2025-04-22T13:24:17.444019+00:00 [queued]>
[2025-04-22T10:24:26.763-0300] {taskinstance.py:2614} INFO - Dependencies all met for dep_context=requeueable deps ti=<TaskInstance: integracao_api.integracao_api manual__2025-04-22T13:24:17.444019+00:00 [queued]>
[2025-04-22T10:24:26.763-0300] {taskinstance.py:2867} INFO - Starting attempt 1 of 3
[2025-04-22T10:24:26.778-0300] {taskinstance.py:2890} INFO - Executing <Task(PythonOperator): integracao_api> on 2025-04-22 13:24:17.444019+00:00
[2025-04-22T10:24:26.783-0300] {standard_task_runner.py:72} INFO - Started process 10991 to run task
[2025-04-22T10:24:26.786-0300] {standard_task_runner.py:104} INFO - Running: ['airflow', 'tasks', 'run', 'integracao_api', 'integracao_api', 'manual__2025-04-22T13:24:17.444019+00:00', '--job-id', '84', '--raw', '--subdir', 'DAGS_FOLDER/dag_integration.py', '--cfg-path', '/tmp/tmpkb46ts7f']
[2025-04-22T10:24:26.787-0300] {standard_task_runner.py:105} INFO - Job 84: Subtask integracao_api
[2025-04-22T10:24:26.827-0300] {task_command.py:467} INFO - Running <TaskInstance: integracao_api.integracao_api manual__2025-04-22T13:24:17.444019+00:00 [running]> on host jonathan-brito
[2025-04-22T10:24:26.899-0300] {taskinstance.py:3134} INFO - Exporting env vars: AIRFLOW_CTX_DAG_OWNER='data_team' AIRFLOW_CTX_DAG_ID='integracao_api' AIRFLOW_CTX_TASK_ID='integracao_api' AIRFLOW_CTX_EXECUTION_DATE='2025-04-22T13:24:17.444019+00:00' AIRFLOW_CTX_TRY_NUMBER='1' AIRFLOW_CTX_DAG_RUN_ID='manual__2025-04-22T13:24:17.444019+00:00'
[2025-04-22T10:24:26.900-0300] {logging_mixin.py:190} INFO - Task instance is in running state
[2025-04-22T10:24:26.900-0300] {logging_mixin.py:190} INFO -  Previous state of the Task instance: queued
[2025-04-22T10:24:26.901-0300] {logging_mixin.py:190} INFO - Current task name:integracao_api state:running start_date:2025-04-22 13:24:26.754530+00:00
[2025-04-22T10:24:26.901-0300] {logging_mixin.py:190} INFO - Dag name:integracao_api and current dag run status:running
[2025-04-22T10:24:26.902-0300] {taskinstance.py:732} INFO - ::endgroup::
[2025-04-22T10:24:26.984-0300] {logging_mixin.py:190} INFO - Erro na requisição: HTTPConnectionPool(host='localhost', port=8000): Max retries exceeded with url: /integration/ (Caused by NewConnectionError('<urllib3.connection.HTTPConnection object at 0x709814d49bb0>: Failed to establish a new connection: [Errno 111] Connection refused'))
[2025-04-22T10:24:26.984-0300] {taskinstance.py:3313} ERROR - Task failed with exception
Traceback (most recent call last):
  File "/home/jonathan-brito/python-projects/airflow/venv/lib/python3.12/site-packages/urllib3/connection.py", line 174, in _new_conn
    conn = connection.create_connection(
           ^^^^^^^^^^^^^^^^^^^^^^^^^^^^^
  File "/home/jonathan-brito/python-projects/airflow/venv/lib/python3.12/site-packages/urllib3/util/connection.py", line 95, in create_connection
    raise err
  File "/home/jonathan-brito/python-projects/airflow/venv/lib/python3.12/site-packages/urllib3/util/connection.py", line 85, in create_connection
    sock.connect(sa)
ConnectionRefusedError: [Errno 111] Connection refused

During handling of the above exception, another exception occurred:

Traceback (most recent call last):
  File "/home/jonathan-brito/python-projects/airflow/venv/lib/python3.12/site-packages/urllib3/connectionpool.py", line 716, in urlopen
    httplib_response = self._make_request(
                       ^^^^^^^^^^^^^^^^^^^
  File "/home/jonathan-brito/python-projects/airflow/venv/lib/python3.12/site-packages/urllib3/connectionpool.py", line 416, in _make_request
    conn.request(method, url, **httplib_request_kw)
  File "/home/jonathan-brito/python-projects/airflow/venv/lib/python3.12/site-packages/urllib3/connection.py", line 244, in request
    super(HTTPConnection, self).request(method, url, body=body, headers=headers)
  File "/usr/lib/python3.12/http/client.py", line 1336, in request
    self._send_request(method, url, body, headers, encode_chunked)
  File "/usr/lib/python3.12/http/client.py", line 1382, in _send_request
    self.endheaders(body, encode_chunked=encode_chunked)
  File "/usr/lib/python3.12/http/client.py", line 1331, in endheaders
    self._send_output(message_body, encode_chunked=encode_chunked)
  File "/usr/lib/python3.12/http/client.py", line 1091, in _send_output
    self.send(msg)
  File "/usr/lib/python3.12/http/client.py", line 1035, in send
    self.connect()
  File "/home/jonathan-brito/python-projects/airflow/venv/lib/python3.12/site-packages/urllib3/connection.py", line 205, in connect
    conn = self._new_conn()
           ^^^^^^^^^^^^^^^^
  File "/home/jonathan-brito/python-projects/airflow/venv/lib/python3.12/site-packages/urllib3/connection.py", line 186, in _new_conn
    raise NewConnectionError(
urllib3.exceptions.NewConnectionError: <urllib3.connection.HTTPConnection object at 0x709814d49bb0>: Failed to establish a new connection: [Errno 111] Connection refused

During handling of the above exception, another exception occurred:

Traceback (most recent call last):
  File "/home/jonathan-brito/python-projects/airflow/venv/lib/python3.12/site-packages/requests/adapters.py", line 667, in send
    resp = conn.urlopen(
           ^^^^^^^^^^^^^
  File "/home/jonathan-brito/python-projects/airflow/venv/lib/python3.12/site-packages/urllib3/connectionpool.py", line 802, in urlopen
    retries = retries.increment(
              ^^^^^^^^^^^^^^^^^^
  File "/home/jonathan-brito/python-projects/airflow/venv/lib/python3.12/site-packages/urllib3/util/retry.py", line 594, in increment
    raise MaxRetryError(_pool, url, error or ResponseError(cause))
urllib3.exceptions.MaxRetryError: HTTPConnectionPool(host='localhost', port=8000): Max retries exceeded with url: /integration/ (Caused by NewConnectionError('<urllib3.connection.HTTPConnection object at 0x709814d49bb0>: Failed to establish a new connection: [Errno 111] Connection refused'))

During handling of the above exception, another exception occurred:

Traceback (most recent call last):
  File "/home/jonathan-brito/python-projects/airflow/venv/lib/python3.12/site-packages/airflow/models/taskinstance.py", line 768, in _execute_task
    result = _execute_callable(context=context, **execute_callable_kwargs)
             ^^^^^^^^^^^^^^^^^^^^^^^^^^^^^^^^^^^^^^^^^^^^^^^^^^^^^^^^^^^^^
  File "/home/jonathan-brito/python-projects/airflow/venv/lib/python3.12/site-packages/airflow/models/taskinstance.py", line 734, in _execute_callable
    return ExecutionCallableRunner(
           ^^^^^^^^^^^^^^^^^^^^^^^^
  File "/home/jonathan-brito/python-projects/airflow/venv/lib/python3.12/site-packages/airflow/utils/operator_helpers.py", line 252, in run
    return self.func(*args, **kwargs)
           ^^^^^^^^^^^^^^^^^^^^^^^^^^
  File "/home/jonathan-brito/python-projects/airflow/venv/lib/python3.12/site-packages/airflow/models/baseoperator.py", line 424, in wrapper
    return func(self, *args, **kwargs)
           ^^^^^^^^^^^^^^^^^^^^^^^^^^^
  File "/home/jonathan-brito/python-projects/airflow/venv/lib/python3.12/site-packages/airflow/operators/python.py", line 238, in execute
    return_value = self.execute_callable()
                   ^^^^^^^^^^^^^^^^^^^^^^^
  File "/home/jonathan-brito/python-projects/airflow/venv/lib/python3.12/site-packages/airflow/operators/python.py", line 256, in execute_callable
    return runner.run(*self.op_args, **self.op_kwargs)
           ^^^^^^^^^^^^^^^^^^^^^^^^^^^^^^^^^^^^^^^^^^^
  File "/home/jonathan-brito/python-projects/airflow/venv/lib/python3.12/site-packages/airflow/utils/operator_helpers.py", line 252, in run
    return self.func(*args, **kwargs)
           ^^^^^^^^^^^^^^^^^^^^^^^^^^
  File "/home/jonathan-brito/python-projects/airflow/dags/dag_integration.py", line 75, in integra_api
    response = requests.post(
               ^^^^^^^^^^^^^^
  File "/home/jonathan-brito/python-projects/airflow/venv/lib/python3.12/site-packages/requests/api.py", line 115, in post
    return request("post", url, data=data, json=json, **kwargs)
           ^^^^^^^^^^^^^^^^^^^^^^^^^^^^^^^^^^^^^^^^^^^^^^^^^^^^
  File "/home/jonathan-brito/python-projects/airflow/venv/lib/python3.12/site-packages/requests/api.py", line 59, in request
    return session.request(method=method, url=url, **kwargs)
           ^^^^^^^^^^^^^^^^^^^^^^^^^^^^^^^^^^^^^^^^^^^^^^^^^
  File "/home/jonathan-brito/python-projects/airflow/venv/lib/python3.12/site-packages/requests/sessions.py", line 589, in request
    resp = self.send(prep, **send_kwargs)
           ^^^^^^^^^^^^^^^^^^^^^^^^^^^^^^
  File "/home/jonathan-brito/python-projects/airflow/venv/lib/python3.12/site-packages/requests/sessions.py", line 703, in send
    r = adapter.send(request, **kwargs)
        ^^^^^^^^^^^^^^^^^^^^^^^^^^^^^^^
  File "/home/jonathan-brito/python-projects/airflow/venv/lib/python3.12/site-packages/requests/adapters.py", line 700, in send
    raise ConnectionError(e, request=request)
requests.exceptions.ConnectionError: HTTPConnectionPool(host='localhost', port=8000): Max retries exceeded with url: /integration/ (Caused by NewConnectionError('<urllib3.connection.HTTPConnection object at 0x709814d49bb0>: Failed to establish a new connection: [Errno 111] Connection refused'))
[2025-04-22T10:24:27.003-0300] {logging_mixin.py:190} INFO - Task instance in failure state
[2025-04-22T10:24:27.003-0300] {logging_mixin.py:190} INFO - Task start:2025-04-22 13:24:26.754530+00:00 end:2025-04-22 13:24:27.003213+00:00 duration:0.248683
[2025-04-22T10:24:27.004-0300] {logging_mixin.py:190} INFO - Task:<Task(PythonOperator): integracao_api> dag:<DAG: integracao_api> dagrun:<DagRun integracao_api @ 2025-04-22 13:24:17.444019+00:00: manual__2025-04-22T13:24:17.444019+00:00, state:running, queued_at: 2025-04-22 13:24:17.475243+00:00. externally triggered: True>
[2025-04-22T10:24:27.004-0300] {logging_mixin.py:190} INFO - Failure caused by HTTPConnectionPool(host='localhost', port=8000): Max retries exceeded with url: /integration/ (Caused by NewConnectionError('<urllib3.connection.HTTPConnection object at 0x709814d49bb0>: Failed to establish a new connection: [Errno 111] Connection refused'))
[2025-04-22T10:24:27.004-0300] {taskinstance.py:1226} INFO - Marking task as UP_FOR_RETRY. dag_id=integracao_api, task_id=integracao_api, run_id=manual__2025-04-22T13:24:17.444019+00:00, execution_date=20250422T132417, start_date=20250422T132426, end_date=20250422T132427
[2025-04-22T10:24:27.039-0300] {taskinstance.py:341} INFO - ::group::Post task execution logs
[2025-04-22T10:24:27.040-0300] {standard_task_runner.py:124} ERROR - Failed to execute job 84 for task integracao_api (HTTPConnectionPool(host='localhost', port=8000): Max retries exceeded with url: /integration/ (Caused by NewConnectionError('<urllib3.connection.HTTPConnection object at 0x709814d49bb0>: Failed to establish a new connection: [Errno 111] Connection refused')); 10991)
Traceback (most recent call last):
  File "/home/jonathan-brito/python-projects/airflow/venv/lib/python3.12/site-packages/urllib3/connection.py", line 174, in _new_conn
    conn = connection.create_connection(
           ^^^^^^^^^^^^^^^^^^^^^^^^^^^^^
  File "/home/jonathan-brito/python-projects/airflow/venv/lib/python3.12/site-packages/urllib3/util/connection.py", line 95, in create_connection
    raise err
  File "/home/jonathan-brito/python-projects/airflow/venv/lib/python3.12/site-packages/urllib3/util/connection.py", line 85, in create_connection
    sock.connect(sa)
ConnectionRefusedError: [Errno 111] Connection refused

During handling of the above exception, another exception occurred:

Traceback (most recent call last):
  File "/home/jonathan-brito/python-projects/airflow/venv/lib/python3.12/site-packages/urllib3/connectionpool.py", line 716, in urlopen
    httplib_response = self._make_request(
                       ^^^^^^^^^^^^^^^^^^^
  File "/home/jonathan-brito/python-projects/airflow/venv/lib/python3.12/site-packages/urllib3/connectionpool.py", line 416, in _make_request
    conn.request(method, url, **httplib_request_kw)
  File "/home/jonathan-brito/python-projects/airflow/venv/lib/python3.12/site-packages/urllib3/connection.py", line 244, in request
    super(HTTPConnection, self).request(method, url, body=body, headers=headers)
  File "/usr/lib/python3.12/http/client.py", line 1336, in request
    self._send_request(method, url, body, headers, encode_chunked)
  File "/usr/lib/python3.12/http/client.py", line 1382, in _send_request
    self.endheaders(body, encode_chunked=encode_chunked)
  File "/usr/lib/python3.12/http/client.py", line 1331, in endheaders
    self._send_output(message_body, encode_chunked=encode_chunked)
  File "/usr/lib/python3.12/http/client.py", line 1091, in _send_output
    self.send(msg)
  File "/usr/lib/python3.12/http/client.py", line 1035, in send
    self.connect()
  File "/home/jonathan-brito/python-projects/airflow/venv/lib/python3.12/site-packages/urllib3/connection.py", line 205, in connect
    conn = self._new_conn()
           ^^^^^^^^^^^^^^^^
  File "/home/jonathan-brito/python-projects/airflow/venv/lib/python3.12/site-packages/urllib3/connection.py", line 186, in _new_conn
    raise NewConnectionError(
urllib3.exceptions.NewConnectionError: <urllib3.connection.HTTPConnection object at 0x709814d49bb0>: Failed to establish a new connection: [Errno 111] Connection refused

During handling of the above exception, another exception occurred:

Traceback (most recent call last):
  File "/home/jonathan-brito/python-projects/airflow/venv/lib/python3.12/site-packages/requests/adapters.py", line 667, in send
    resp = conn.urlopen(
           ^^^^^^^^^^^^^
  File "/home/jonathan-brito/python-projects/airflow/venv/lib/python3.12/site-packages/urllib3/connectionpool.py", line 802, in urlopen
    retries = retries.increment(
              ^^^^^^^^^^^^^^^^^^
  File "/home/jonathan-brito/python-projects/airflow/venv/lib/python3.12/site-packages/urllib3/util/retry.py", line 594, in increment
    raise MaxRetryError(_pool, url, error or ResponseError(cause))
urllib3.exceptions.MaxRetryError: HTTPConnectionPool(host='localhost', port=8000): Max retries exceeded with url: /integration/ (Caused by NewConnectionError('<urllib3.connection.HTTPConnection object at 0x709814d49bb0>: Failed to establish a new connection: [Errno 111] Connection refused'))

During handling of the above exception, another exception occurred:

Traceback (most recent call last):
  File "/home/jonathan-brito/python-projects/airflow/venv/lib/python3.12/site-packages/airflow/task/task_runner/standard_task_runner.py", line 117, in _start_by_fork
    ret = args.func(args, dag=self.dag)
          ^^^^^^^^^^^^^^^^^^^^^^^^^^^^^
  File "/home/jonathan-brito/python-projects/airflow/venv/lib/python3.12/site-packages/airflow/cli/cli_config.py", line 49, in command
    return func(*args, **kwargs)
           ^^^^^^^^^^^^^^^^^^^^^
  File "/home/jonathan-brito/python-projects/airflow/venv/lib/python3.12/site-packages/airflow/utils/cli.py", line 116, in wrapper
    return f(*args, **kwargs)
           ^^^^^^^^^^^^^^^^^^
  File "/home/jonathan-brito/python-projects/airflow/venv/lib/python3.12/site-packages/airflow/cli/commands/task_command.py", line 483, in task_run
    task_return_code = _run_task_by_selected_method(args, _dag, ti)
                       ^^^^^^^^^^^^^^^^^^^^^^^^^^^^^^^^^^^^^^^^^^^^
  File "/home/jonathan-brito/python-projects/airflow/venv/lib/python3.12/site-packages/airflow/cli/commands/task_command.py", line 256, in _run_task_by_selected_method
    return _run_raw_task(args, ti)
           ^^^^^^^^^^^^^^^^^^^^^^^
  File "/home/jonathan-brito/python-projects/airflow/venv/lib/python3.12/site-packages/airflow/cli/commands/task_command.py", line 341, in _run_raw_task
    return ti._run_raw_task(
           ^^^^^^^^^^^^^^^^^
  File "/home/jonathan-brito/python-projects/airflow/venv/lib/python3.12/site-packages/airflow/utils/session.py", line 97, in wrapper
    return func(*args, session=session, **kwargs)
           ^^^^^^^^^^^^^^^^^^^^^^^^^^^^^^^^^^^^^^
  File "/home/jonathan-brito/python-projects/airflow/venv/lib/python3.12/site-packages/airflow/models/taskinstance.py", line 3006, in _run_raw_task
    return _run_raw_task(
           ^^^^^^^^^^^^^^
  File "/home/jonathan-brito/python-projects/airflow/venv/lib/python3.12/site-packages/airflow/models/taskinstance.py", line 274, in _run_raw_task
    TaskInstance._execute_task_with_callbacks(
  File "/home/jonathan-brito/python-projects/airflow/venv/lib/python3.12/site-packages/airflow/models/taskinstance.py", line 3161, in _execute_task_with_callbacks
    result = self._execute_task(context, task_orig)
             ^^^^^^^^^^^^^^^^^^^^^^^^^^^^^^^^^^^^^^
  File "/home/jonathan-brito/python-projects/airflow/venv/lib/python3.12/site-packages/airflow/models/taskinstance.py", line 3185, in _execute_task
    return _execute_task(self, context, task_orig)
           ^^^^^^^^^^^^^^^^^^^^^^^^^^^^^^^^^^^^^^^
  File "/home/jonathan-brito/python-projects/airflow/venv/lib/python3.12/site-packages/airflow/models/taskinstance.py", line 768, in _execute_task
    result = _execute_callable(context=context, **execute_callable_kwargs)
             ^^^^^^^^^^^^^^^^^^^^^^^^^^^^^^^^^^^^^^^^^^^^^^^^^^^^^^^^^^^^^
  File "/home/jonathan-brito/python-projects/airflow/venv/lib/python3.12/site-packages/airflow/models/taskinstance.py", line 734, in _execute_callable
    return ExecutionCallableRunner(
           ^^^^^^^^^^^^^^^^^^^^^^^^
  File "/home/jonathan-brito/python-projects/airflow/venv/lib/python3.12/site-packages/airflow/utils/operator_helpers.py", line 252, in run
    return self.func(*args, **kwargs)
           ^^^^^^^^^^^^^^^^^^^^^^^^^^
  File "/home/jonathan-brito/python-projects/airflow/venv/lib/python3.12/site-packages/airflow/models/baseoperator.py", line 424, in wrapper
    return func(self, *args, **kwargs)
           ^^^^^^^^^^^^^^^^^^^^^^^^^^^
  File "/home/jonathan-brito/python-projects/airflow/venv/lib/python3.12/site-packages/airflow/operators/python.py", line 238, in execute
    return_value = self.execute_callable()
                   ^^^^^^^^^^^^^^^^^^^^^^^
  File "/home/jonathan-brito/python-projects/airflow/venv/lib/python3.12/site-packages/airflow/operators/python.py", line 256, in execute_callable
    return runner.run(*self.op_args, **self.op_kwargs)
           ^^^^^^^^^^^^^^^^^^^^^^^^^^^^^^^^^^^^^^^^^^^
  File "/home/jonathan-brito/python-projects/airflow/venv/lib/python3.12/site-packages/airflow/utils/operator_helpers.py", line 252, in run
    return self.func(*args, **kwargs)
           ^^^^^^^^^^^^^^^^^^^^^^^^^^
  File "/home/jonathan-brito/python-projects/airflow/dags/dag_integration.py", line 75, in integra_api
    response = requests.post(
               ^^^^^^^^^^^^^^
  File "/home/jonathan-brito/python-projects/airflow/venv/lib/python3.12/site-packages/requests/api.py", line 115, in post
    return request("post", url, data=data, json=json, **kwargs)
           ^^^^^^^^^^^^^^^^^^^^^^^^^^^^^^^^^^^^^^^^^^^^^^^^^^^^
  File "/home/jonathan-brito/python-projects/airflow/venv/lib/python3.12/site-packages/requests/api.py", line 59, in request
    return session.request(method=method, url=url, **kwargs)
           ^^^^^^^^^^^^^^^^^^^^^^^^^^^^^^^^^^^^^^^^^^^^^^^^^
  File "/home/jonathan-brito/python-projects/airflow/venv/lib/python3.12/site-packages/requests/sessions.py", line 589, in request
    resp = self.send(prep, **send_kwargs)
           ^^^^^^^^^^^^^^^^^^^^^^^^^^^^^^
  File "/home/jonathan-brito/python-projects/airflow/venv/lib/python3.12/site-packages/requests/sessions.py", line 703, in send
    r = adapter.send(request, **kwargs)
        ^^^^^^^^^^^^^^^^^^^^^^^^^^^^^^^
  File "/home/jonathan-brito/python-projects/airflow/venv/lib/python3.12/site-packages/requests/adapters.py", line 700, in send
    raise ConnectionError(e, request=request)
requests.exceptions.ConnectionError: HTTPConnectionPool(host='localhost', port=8000): Max retries exceeded with url: /integration/ (Caused by NewConnectionError('<urllib3.connection.HTTPConnection object at 0x709814d49bb0>: Failed to establish a new connection: [Errno 111] Connection refused'))
[2025-04-22T10:24:27.079-0300] {local_task_job_runner.py:266} INFO - Task exited with return code 1
[2025-04-22T10:24:27.097-0300] {taskinstance.py:3901} INFO - 0 downstream tasks scheduled from follow-on schedule check
[2025-04-22T10:24:27.098-0300] {local_task_job_runner.py:245} INFO - ::endgroup::
